// Error handling utility functions
const catchAsync = (fn) => {
  return (req, res, next) => {
    Promise.resolve(fn(req, res, next)).catch(next);
  };
};

class APIError extends Error {
  constructor(message, statusCode) {
    super(message);
    this.statusCode = statusCode;
    this.status = `${statusCode}`.startsWith('4') ? 'fail' : 'error';
    this.isOperational = true;

    Error.captureStackTrace(this, this.constructor);
  }
}

const errorHandler = (err, req, res, next) => {
  err.statusCode = err.statusCode || 500;
  err.status = err.status || 'error';

  if (process.env.NODE_ENV === 'development') {
    res.status(err.statusCode).json({
      status: err.status,
      error: err,
      message: err.message,
      stack: err.stack
    });
  } else {
    // Production
    if (err.isOperational) {
      res.status(err.statusCode).json({
        status: err.status,
        message: err.message
      });
    } else {
      console.error('ERROR ðŸ’¥', err);
      res.status(500).json({
        status: 'error',
        message: 'Something went wrong!'
      });
    }
  }
};

module.exports = {
  catchAsync,
  APIError,
  errorHandler
};
